Workbook
Name LEGENDS: [1]Sheet4!$A$6:$A$29
Name MEAU: [2]PL1!$A$1:$L$178

Sheet Progress
A1: TATA PROJECTS LIMITED
A2: PROJECT NAME: PIPING PROJECT (340092) | K2: Progress as on | L2: 44492
A3: DAILY PROGRESS REPORT | K3: Report Date | L3: =L2 -> 44492
M4: 11550
A5: S.No | B5: Description | C5: Unit | D5: Total Scope | E5: Progress upto previous month | F5: Planned for the month | G5: Progress For the Month | J5: Upto date progress | K5: Balance | L5: Remarks
G6: Till Yesterday | H6: Today | I6: Cumm. | O6: Till
A8: A | B8: Supply
A9: 1 | B9: Pipes( Receiving at site) | C9: Mtr | D9: 107231 | E9: 95680 | F9: 5000 | G9: 0 | I9: =G9+H9 -> 0 | J9: 95680 | K9: =11.55*1000 -> 11550
B10: Blasting | C10: Mtr | D10: 75182 | E10: 49495 | F10: 6000 | G10: 3066.93 | I10: =G10+H10 -> 3066.93 | J10: =I10+E10 -> 52561.93 | K10: =D10-J10 -> 22620.07 | M10: =47831.38-J10 -> -4730.55 | N10: =47831.38-J10 -> -4730.55 | O10: 16-Sep
B11: Painting (Primer) | C11: Mtr | D11: 75182 | E11: 49495 | F11: 6000 | G11: 3066.93 | I11: =G11+H11 -> 3066.93 | J11: =I11+E11 -> 52561.93 | K11: =D11-J11 -> 22620.07 | O11: 16-Sep
A12: 2 | B12: Flanges | C12: Nos | D12: 5821 | E12: 21323 | F12: 300 | G12: 0 | I12: =G12+H12 -> 0 | J12: 21323 | K12: 75709
A13: 3 | B13: Fittings | C13: Nos | D13: 16737 | E13: 14433 | F13: 200 | G13: 0 | I13: =G13+H13 -> 0 | J13: =E13+I13 -> 14433 | K13: =D13-J13 -> 2304
A14: 4 | B14: Strainers | C14: Nos | D14: 30 | E14: 0 | G14: 0 | I14: =G14+H14 -> 0 | J14: =E14+I14 -> 0 | K14: =D14-J14 -> 30
A15: 5 | B15: Gaskets | C15: Nos | D15: 3993 | E15: 0 | G15: 0 | I15: =G15+H15 -> 0 | J15: =E15+I15 -> 0 | K15: =D15-J15 -> 3993
A16: 6 | B16: Fasteners | C16: Nos | D16: 22544 | E16: 0 | G16: 0 | I16: =G16+H16 -> 0 | J16: =E16+I16 -> 0 | K16: =D16-J16 -> 22544
A17: 7 | B17: Valves | C17: Nos | D17: 2611 | E17: 0 | F17: 350 | G17: 0 | I17: =G17+H17 -> 0 | J17: =E17+I17 -> 0 | K17: =D17-J17 -> 2611
A19: B | B19: Mechanical
A20: 1 | B20: Fabrication of Pipe Specials | C20: Nos | D20: 1 | E20: 0 | G20: 0 | I20: =G20+H20 -> 0 | J20: =E20+I20 -> 0 | K20: =D20-J20 -> 1 | L20: Pipe Sleeper : Precasted = 2436 nos Shifted = 1282 nos Placed = 1282 nos Backfilled = 1020 nos
A21: 2 | B21: CS-Fabrication of Pipe (Butt Weld) Thk<=10 MM | C21: ID | D21: 123470 | E21: 0 | G21: 0 | I21: =G21+H21 -> 0 | J21: =E21+I21 -> 0 | K21: =D21-J21 -> 123470 | M21: =18608-J22 -> -11066
B22: Fitup | C22: ID | D22: 123470 | E22: 22022 | F22: 10000 | G22: 7574 | H22: 78 | I22: =G22+H22 -> 7652 | J22: =I22+E22 -> 29674 | K22: =D22-J22 -> 93796 | O22: 23-Sep
B23: Welding | C23: ID | D23: 123470 | E23: 22022 | F23: 10000 | G23: 7422.5 | H23: 274 | I23: =G23+H23 -> 7696.5 | J23: =I23+E23 -> 29718.5 | K23: =D23-J23 -> 93751.5 | O23: 23-Sep
A24: 3 | B24: CS-Fabrication of Pipe (Fillet Weld) Thk<=10 MM | C24: ID | D24: 28140 | E24: 57 | G24: 0 | I24: =G24+H24 -> 0 | J24: 57 | K24: =D24-J24 -> 28083
A25: 4 | B25: Erection (Other than Spools) : CS | C25: IM | D25: 604060 | E25: 0 | G25: 0 | I25: =G25+H25 -> 0 | J25: =E25+I25 -> 0 | K25: =D25-J25 -> 604060
B26: Placing | C26: IM | D26: 489572 | E26: 146598 | F26: 40000 | G26: 35441.88 | H26: 1728 | I26: =G26+H26 -> 37169.88 | J26: =I26+E26 -> 183767.88 | K26: =D26-J26 -> 305804.12 | O26: 21-Sep
B27: Alignment & Hydrotest | C27: IM | D27: 604060 | E27: 6000 | J27: 6000 | K27: =D27-J27 -> 598060
A28: 5 | B28: SS-Fabrication of Pipe (Butt Weld) Thk<=10 MM | C28: ID | D28: 5100 | E28: 0 | G28: 0 | I28: =G28+H28 -> 0 | J28: =E28+I28 -> 0 | K28: =D28-J28 -> 5100
A29: 6 | B29: SS-Fabrication of Pipe (Fillet Weld) Thk<=10 MM | C29: ID | D29: 5430 | E29: 0 | G29: 0 | I29: =G29+H29 -> 0 | J29: =E29+I29 -> 0 | K29: =D29-J29 -> 5430
A30: 7 | B30: Erection (Other than Spools) : SS | C30: IM | D30: 22865 | E30: 0 | G30: 0 | I30: =G30+H30 -> 0 | J30: =E30+I30 -> 0 | K30: =D30-J30 -> 22865
A31: 8 | B31: Carbon Steel Galvanized | C31: Mtr | D31: 35010 | E31: 486 | G31: 0 | I31: =G31+H31 -> 0 | J31: 486 | K31: =D31-J31 -> 34524
A32: 9 | B32: Rubber Lined Piping | C32: Mtr | D32: 2000 | E32: 0 | G32: 0 | I32: =G32+H32 -> 0 | J32: =E32+I32 -> 0 | K32: =D32-J32 -> 2000
A33: 10 | B33: Valves - Flanged / Wafer Valves | C33: Nos | D33: 1167 | E33: 0 | G33: 0 | I33: =G33+H33 -> 0 | J33: =E33+I33 -> 0 | K33: =D33-J33 -> 1167
A34: 11 | B34: Valves - Control Valves | C34: Nos | D34: 98 | E34: 0 | G34: 0 | I34: =G34+H34 -> 0 | J34: =E34+I34 -> 0 | K34: =D34-J34 -> 98
A35: 12 | B35: Valves - Rubber Lined Valves | C35: Nos | D35: 39 | E35: 0 | G35: 0 | I35: =G35+H35 -> 0 | J35: =E35+I35 -> 0 | K35: =D35-J35 -> 39
A36: 13 | B36: Valves - Press Relief / Safety Valves | C36: Nos | D36: 79 | E36: 0 | G36: 0 | I36: =G36+H36 -> 0 | J36: =E36+I36 -> 0 | K36: =D36-J36 -> 79
A37: 14 | B37: Bolt Tensioning | C37: Nos | D37: 6 | E37: 0 | G37: 0 | I37: =G37+H37 -> 0 | J37: =E37+I37 -> 0 | K37: =D37-J37 -> 6
A38: 15 | B38: Reinforcing Pipes for Pads | C38: Nos | D38: 29 | E38: 0 | G38: 0 | I38: =G38+H38 -> 0 | J38: =E38+I38 -> 0 | K38: =D38-J38 -> 29
A39: 16 | B39: Radiography - For Joints THK. <= 8MM (FOR CS than Class IV ) | C39: Nos | D39: 1400 | E39: 78 | J39: 78 | K39: =D39-J39 -> 1322 | O39: 24-Sep
A40: 17 | B40: Radiography - For Joints THK. <= 8MM (FOR CS as per Class IV ) | C40: Nos | D40: 262 | E40: 0 | G40: 0 | I40: =G40+H40 -> 0 | J40: =E40+I40 -> 0 | K40: =D40-J40 -> 262 | O40: 24-Sep
A41: 18 | B41: Radiography - For Joints above THK. 8MM | C41: Nos | D41: 1725 | E41: 26 | F41: 20 | G41: 0 | I41: =G41+H41 -> 0 | J41: 26 | K41: =D41-J41 -> 1699 | O41: 24-Sep
A42: 19 | B42: DYE Penetration / Magnetic Particle test | C42: Inches | D42: 3686 | E42: 188.4 | F42: 200 | G42: 0 | I42: =G42+H42 -> 0 | J42: =E42+I42 -> 188.4 | K42: =D42-J42 -> 3497.6 | O42: 24-Sep
...

Sheet  Manpower & Machinery
A1: TATA PROJECT LIMITED
A2: DAILY MANPOWER & MACHINERY REPORT
A3: PROJECT: PIPING PROJECT (340092) | E3: Progress as on | H3: 44492
E4: Report Date | H4: 44492
A6: Sr. No. | B6: Category | C6: TPL | D6: Sub-Contractor | H6: Total
D7: Artson - Pipe Rack Structure | E7: Lansh - Piping work | F7: SLG - Grating & Handrail work. | G7: ICCPL - Fire Protection Work
A8: Staff
A9: 1 | B9: RCM | C9: 1 | D9: 1 | H9: =SUM(C9:G9) -> 2
A10: 2 | B10: Site Incharge | C10: 1 | D10: 2 | E10: 1 | H10: =SUM(C10:G10) -> 4
A11: 3 | B11: Planning Manager/ Engineer | C11: 1 | D11: 1 | E11: 3 | H11: =SUM(C11:G11) -> 5
A12: 4 | B12: Document Controller | H12: =SUM(C12:G12) -> 0
A13: 5 | B13: Structural Engineer/Manager | C13: 2 | D13: 3 | H13: =SUM(C13:G13) -> 5
A14: 6 | B14: Structural Supervisor | D14: 8 | H14: =SUM(C14:G14) -> 8
A15: 7 | B15: Piping Engineer/Manager | C15: 2 | E15: 5 | H15: =SUM(C15:G15) -> 7
A16: 8 | B16: Piping Supervisor | E16: 0 | H16: =SUM(C16:G16) -> 0
A17: 9 | B17: Equipment Engineer | E17: 0 | H17: =SUM(C17:G17) -> 0
A18: 10 | B18: Equipment Supervisor | H18: =SUM(C18:G18) -> 0
A19: 11 | B19: Erection Foreman | C19: 1 | D19: 1 | H19: =SUM(C19:G19) -> 2
A20: 12 | B20: Electrician | C20: 1 | E20: 0 | H20: =SUM(C20:G20) -> 1
A21: 13 | B21: SCM | C21: 1 | H21: =SUM(C21:G21) -> 1
A22: 14 | B22: Stores Incharge | C22: 1 | E22: 1 | H22: =SUM(C22:G22) -> 2
A23: 15 | B23: Stores Assistant | C23: 1 | E23: 1 | H23: =SUM(C23:G23) -> 2
A24: 16 | B24: HR & Admin | D24: 1 | E24: 1 | H24: =SUM(C24:G24) -> 2
A25: 17 | B25: EHS Incharge | C25: 1 | H25: =SUM(C25:G25) -> 1
A26: 18 | B26: EHS Officer | C26: 1 | D26: 1 | E26: 1 | H26: =SUM(C26:G26) -> 3
A27: 19 | B27: EHS Steward | H27: =SUM(C27:G27) -> 0
A28: 20 | B28: Quality Engineer/Manager | C28: 2 | D28: 1 | E28: 1 | H28: =SUM(C28:G28) -> 4
A29: 21 | B29: Quality Supervisor | D29: 8 | H29: =SUM(C29:G29) -> 8
A30: 22 | B30: Surveyor | C30: 1 | D30: 0 | H30: =SUM(C30:G30) -> 1
A31: 23 | B31: Facility Engineer | H31: =SUM(C31:G31) -> 0
B32: TOTAL | C32: =SUM(C9:C31) -> 17 | D32: =SUM(D9:D31) -> 27 | E32: 14 | H32: =SUM(H9:H31) -> 58
A33: Workmen
A34: 24 | B34: Mechanic | H34: =SUM(C34:G34) -> 0
A35: 25 | B35: Crane Operator | E35: 1 | H35: =SUM(C35:G35) -> 1
A36: 26 | B36: Hydra Operator | D36: 4 | E36: 2 | H36: =SUM(C36:G36) -> 6
A37: 27 | B37: Trailor Operator | E37: 1 | H37: =SUM(C37:G37) -> 1
A38: 28 | B38: scafolding | E38: 7 | H38: =SUM(C38:G38) -> 7
A39: 29 | B39: Fitter | D39: 18 | E39: 9 | H39: =SUM(C39:G39) -> 27
A40: 30 | B40: Welder | D40: 21 | E40: 19 | H40: =SUM(C40:G40) -> 40
A41: 31 | B41: Rigger | D41: 27 | E41: 30 | F41: 3 | G41: 2 | H41: =SUM(C41:G41) -> 62
...

Sheet Pipe Rack Status
A1: Pipe Rack Tracking as on 23-Oct-2021
A3: Sl. No. | B3: Area | C3: Type of footings | D3: Number of Footings | E3: Number of footings casted | F3: Number of footings balance | G3: Number of footings under hold | H3: Total number of design Drawings | I3: Number of drawings cleared | J3: Number of drawings pending | K3: Structure Tonnage as per design drawing | L3: Priority | M3: Any other Constraint (foundation,drawing,hold information) | N3: Material (Str) received at site | O3: Material (Str) erected Till now | P3: Working Status
A4: 1 | B4: Area-1 | C4: Foundation | D4: 31 | E4: 21 | F4: =D4-E4 -> 10 | G4: 0 | H4: 6 | I4: =H4-J4 -> 6 | J4: 0 | K4: 223 | L4: Priority-3 | N4: 100.1 | O4: 69.2 | P4: ERECTION OF TIE MEMBERS
C5: T-Sleeper | D5: 0 | E5: 0 | F5: =D5-E5 -> 0 | G5: 0 | H5: 0 | I5: 0 | J5: 0
A6: 2 | B6: Area-2 | C6: Foundation | D6: 25 | E6: 11 | F6: =D6-E6 -> 14 | G6: 0 | H6: 5 | I6: =H6-J6 -> 5 | J6: 0 | K6: 134 | L6: Priority-3 | N6: 128 | O6: 27.2 | P6: ERECTION OF PORTALS
C7: T-Sleeper | D7: 0 | E7: 0 | F7: =D7-E7 -> 0 | G7: 0 | H7: 0 | I7: 0 | J7: 0
A8: 3 | B8: Area-3 | C8: Foundation | D8: 30 | E8: 0 | F8: =D8-E8 -> 30 | G8: 0 | H8: 5 | I8: =H8-J8 -> 5 | J8: 0 | K8: 147 | L8: Priority-3 | N8: 151.7 | O8: 44.2
C9: T-Sleeper | D9: 0 | E9: 0 | F9: =D9-E9 -> 0 | G9: 0 | H9: 0 | I9: 0 | J9: 0
A10: 4 | B10: Area-4 | C10: Foundation | D10: 33 | E10: 17 | F10: =D10-E10 -> 16 | G10: 0 | H10: 6 | I10: =H10-J10 -> 6 | J10: 0 | K10: 199 | L10: Priority-3 | N10: 180.7 | O10: 43.4 | P10: ERECTION OF PORTALS & ERECTION OF PORTALS
C11: T-Sleeper | D11: 0 | E11: 0 | F11: =D11-E11 -> 0 | G11: 0 | H11: 0 | I11: 0 | J11: 0
A12: 5 | B12: Area-5 | C12: Foundation | D12: 33 | E12: 33 | F12: =D12-E12 -> 0 | G12: 0 | H12: 4 | I12: =H12-J12 -> 4 | J12: 0 | K12: 123 | L12: Priority-2 | N12: 122.9 | O12: 86 | P12: ERECTION OF TIE MEMBERS
C13: T-Sleeper | D13: 0 | E13: 0 | F13: =D13-E13 -> 0 | G13: 0 | H13: 0 | I13: 0 | J13: 0
A14: 6 | B14: Area-6 | C14: Foundation | D14: 43 | E14: 39 | F14: =D14-E14 -> 4 | G14: 0 | H14: 7 | I14: =H14-J14 -> 7 | J14: 0 | K14: 237 | L14: Priority-1B | N14: 318.7 | O14: 235.2 | P14: ERECTION OF GALLERY
C15: T-Sleeper | D15: 0 | E15: 0 | F15: =D15-E15 -> 0 | G15: 0 | H15: 0 | I15: 0 | J15: 0
A16: 7 | B16: Area-7 | C16: Foundation | D16: 25 | E16: 24 | F16: =D16-E16 -> 1 | G16: 0 | H16: 6 | I16: =H16-J16 -> 6 | J16: 0 | K16: 154 | L16: Priority-1A | M16: Need Foundation handover from Plants & Non-Plants | N16: 160.6 | O16: 160.6 | P16: ERECTION OF CABLE DUCTS
C17: T-Sleeper | D17: 0 | E17: 0 | F17: =D17-E17 -> 0 | G17: 0 | H17: 0 | I17: 0 | J17: 0
A18: 8 | B18: Area-8 | C18: Foundation | D18: 0 | E18: 0 | F18: =D18-E18 -> 0 | G18: 0 | H18: 0 | I18: =H18-J18 -> 0 | J18: 0 | N18: 0
C19: T-Sleeper | D19: 33 | E19: 0 | F19: =D19-E19 -> 33 | G19: 0 | H19: 1 | I19: 0 | J19: 0
A20: 9 | B20: Area-9 | C20: Foundation | D20: 26 | E20: 26 | F20: =D20-E20 -> 0 | G20: 0 | H20: 9 | I20: =H20-J20 -> 9 | J20: 0 | K20: 311 | L20: Priority-1A | M20: Need Foundation handover from Plants & Non-Plants | N20: 285 | O20: 282.2 | P20: erection of tie MEMBERS
C21: T-Sleeper | D21: 0 | E21: 0 | F21: =D21-E21 -> 0 | G21: 0 | H21: 0 | I21: 0 | J21: 0
A22: 10 | B22: Area-10 | C22: Foundation | D22: 43 | E22: 43 | F22: =D22-E22 -> 0 | G22: 0 | H22: 5 | I22: =H22-J22 -> 5 | J22: 0 | K22: 245 | L22: Priority-1A | N22: 264.6 | O22: 261.2 | P22: erection of PORTALS
C23: T-Sleeper | D23: 0 | E23: 0 | F23: =D23-E23 -> 0 | G23: 0 | H23: 0 | I23: 0 | J23: 0
A24: 11 | B24: Area-11 | C24: Foundation | D24: 24 | E24: 24 | F24: =D24-E24 -> 0 | G24: 0 | H24: 8 | I24: =H24-J24 -> 8 | J24: 0 | K24: 231 | L24: Priority-1A | N24: 172.4 | O24: 172.4 | P24: erection of tie MEMBERS
C25: T-Sleeper | D25: 0 | E25: 0 | F25: =D25-E25 -> 0 | G25: 0 | H25: 0 | I25: 0 | J25: 0
A26: 12 | B26: Area-12 | C26: Foundation | D26: 22 | E26: 22 | F26: =D26-E26 -> 0 | G26: 0 | H26: 5 | I26: =H26-J26 -> 5 | J26: 0 | K26: 131 | L26: Priority-1B | N26: 134.3 | O26: 125.9 | P26: erection of beam and bracing
C27: T-Sleeper | D27: 0 | E27: 0 | F27: =D27-E27 -> 0 | G27: 0 | H27: 0 | I27: 0 | J27: 0
A28: 13 | B28: Area-13 | C28: Foundation | D28: 23 | E28: 19 | F28: =D28-E28 -> 4 | G28: 0 | H28: 6 | I28: =H28-J28 -> 6 | J28: 0 | K28: 155 | L28: Priority-2 | N28: 160.1 | O28: 122.6 | P28: FIT-UP OF GALLERY
C29: T-Sleeper | D29: 0 | E29: 0 | F29: =D29-E29 -> 0 | G29: 0 | H29: 0 | I29: 0 | J29: 0
A30: 14 | B30: Area-14 | C30: Foundation | D30: 29 | E30: 0 | F30: =D30-E30 -> 29 | G30: 0 | H30: 9 | I30: =H30-J30 -> 8 | J30: 1 | K30: 315 | L30: Priority-3 | N30: 108
C31: T-Sleeper | D31: 0 | E31: 0 | F31: =D31-E31 -> 0 | G31: 0 | H31: 0 | I31: 0 | J31: 0
A32: 15 | B32: Area-15 | C32: Foundation | D32: 40 | E32: 35 | F32: =D32-E32 -> 5 | G32: 0 | H32: 10 | I32: =H32-J32 -> 10 | J32: 0 | K32: 332 | L32: Priority-2 | M32: 7 Foundations under hold | N32: 237.6 | O32: 193.5 | P32: ERECTION OF BRIDGE COLUMN (BOX-UP)
C33: T-Sleeper | D33: 0 | E33: 0 | F33: =D33-E33 -> 0 | G33: 0 | H33: 0 | I33: 0 | J33: 0
A34: 16 | B34: Area-16 | C34: Foundation | D34: 52 | E34: 26 | F34: =D34-E34 -> 26 | G34: 0 | H34: 9 | I34: =H34-J34 -> 8 | J34: 1 | K34: 286 | L34: Priority-1C | M34: 7 Foundations under hold | N34: 287.6 | O34: 110.3 | P34: WELDING & ASSEMBLY OF PORTALS/ERECTION OF PORTALS
C35: T-Sleeper | D35: 0 | E35: 0 | F35: =D35-E35 -> 0 | G35: 0 | H35: 0 | I35: 0 | J35: 0
A36: 17 | B36: Area-17 | C36: Foundation | D36: 0 | E36: 0 | F36: =D36-E36 -> 0 | G36: 0 | H36: 0 | I36: =H36-J36 -> 0 | J36: 0
C37: T-Sleeper | D37: 31 | E37: 0 | F37: =D37-E37 -> 31 | G37: 0 | H37: 1 | I37: 0 | J37: 0
A38: 18 | B38: Area-18 | C38: Foundation | D38: 0 | E38: 0 | F38: =D38-E38 -> 0 | G38: 0 | H38: 0 | I38: =H38-J38 -> 0 | J38: 0
C39: T-Sleeper | D39: 20 | E39: 0 | F39: =D39-E39 -> 20 | G39: 0 | H39: 1 | I39: 0 | J39: 0
A40: 19 | B40: Area-19 | C40: Foundation | D40: 0 | E40: 0 | F40: =D40-E40 -> 0 | G40: 0 | H40: 0 | I40: =H40-J40 -> 0 | J40: 0
C41: T-Sleeper | D41: 61 | E41: 0 | F41: =D41-E41 -> 61 | G41: 0 | H41: 1 | I41: 0 | J41: 0
...

Sheet Pipe Rack Constraint
A1: List of Super Structural Drawings pending from EIL/NFC - As on date 10-Oct-2021
A3: Pipe Rack Structure - GAD/Design Drawing
A4: Sl.No. | B4: Area No. | C4: Drawing No. | D4: Observations | E4: Remarks | F4: STATUS as on date
A5: 1 | B5: Area-1 | C5: A367-040-16-48-00701 | D5: Area 1 FDN drg 00701 issued on 25.08.20 by EIL, but drg not received from NFC. | F5: Resolved, Drg. Received on 16-12-2020
A6: =A5+1 -> 2 | C6: A367-040-81-41-06704; R-2 | D6: Descrepancy in the TOG elevation of Grid 1-19/38 & Grid 20/38, Because the Tier-1 from 15-01 (A367-040-81-41-06774; R-1) is fouling wih the concrete column of Grid 1-19/38 & Grid 1-20/38. | E6: Area-1 fabricated pipe rack structures are started to receive at site. | F6: Resolved, on date 10-12-2020
A7: =A6+1 -> 3 | B7: Area-15 | C7: A367-040-81-41-06774; R-1 | F7: Resolved, on date 10-12-2020
A8: =A7+1 -> 4 | C8: A367-040-16-48-00771 | F8: Pipe Rack & Pipe Bridge - 7 Foundation HOLD released by NFC. Foundations casting pending.
A9: =A8+1 -> 5 | C9: A367-040-16-48-00772
A10: =A9+1 -> 6 | C10: A367-040-16-48-00773
A11: =A10+1 -> 7 | C11: A367-040-81-41-06774
A12: =A11+1 -> 8 | C12: A367-040-81-41-06784
A13: =A7+1 -> 4 | B13: Area-4 | C13: A367-040-16-48-00716; R-3 | D13: In this foundation layout drawing, the grid 4-04 & 4-05 is marked as HOLD, but in super structure drawing the same is not marked, need clarification. | E13: Already replied this thing on receipt of the drawing. | F13: Resolved, Drg. Received on 16-12-2020
A14: =A13+1 -> 5 | B14: Area-6 | C14: A367-040-81-41-06732; R-2 | D14: Mismatch of connecting beam (Tier-1) level to pipe bridge. Same is marked on the RFI drawing shared through mail. | F14: Clarified on 29-12-2020 & found O.K. w.r.t. the latest revision
A15: =A14+1 -> 6 | C15: A367-040-16-48-00726; R-3 | D15: Grid 6-41 & 6-42 is kept under hold by EIL for the purpose of some changes in piping GAD may affect this grid. | E15: Recent comment by EIL. | F15: Resolved
A16: =A15+1 -> 7 | B16: Area-14 | C16: A367-040-16-48-00766 | D16: Due to change in Road location for Extrusion Bldg, Client (Civil Dept) may revise the foundation layout. Due to this reason detail engg not done. | F16: Resolved
A17: =A16+1 -> 8 | C17: A367-040-16-48-00767 | F17: Resolved
A18: =A17+1 -> 9 | C18: A367-040-16-48-00768 | F18: Resolved
A19: =A18+1 -> 10 | C19: A367-040-81-41-06769 | F19: Resolved
A20: =A19+1 -> 11 | C20: A367-040-81-41-06770 | F20: Resolved
A21: =A20+1 -> 12 | C21: A367-040-81-41-06771 | F21: Resolved
A22: =A21+1 -> 13 | C22: A367-040-81-41-06772 | F22: Resolved
A23: =A22+1 -> 14 | C23: A367-040-81-41-06773 | F23: Resolved
A24: =A23+1 -> 15 | C24: A367-040-16-48-06775 | F24: Resolved
A25: =A24+1 -> 16 | B25: Area-16 | C25: A367-040-16-48-00776 | D25: 7 Foundation got hold by NFC CIVIL Dept(on fouling with some structure) | F25: Pipe Rack & Pipe Bridge - 7 Foundation HOLD released by NFC. Foundations casting pending.
A26: =A25+1 -> 17 | C26: A367-040-16-48-00777
A27: =A26+1 -> 18 | C27: A367-040-16-48-00778
A28: =A27+1 -> 19 | C28: A367-040-81-41-06779
A29: =A28+1 -> 20 | C29: A367-040-81-41-06787; R-1
A30: =A28+1 -> 20 | C30: A367-040-81-41-06789 | D30: Revised bridge drawing required. | F30: Resolved, Drg. Received on 22-12-2020
A31: =A30+1 -> 21 | C31: A367-040-81-41-06786; R-1 | D31: Due to the above reason detail engg not done for this bridge super structure too in co-relation with the pipe rack super structure. So EIL shall confirm the latest revision. | F31: Detail Engg is under progress from TPL end.
A32: =A31+1 -> 22 | C32: A367-040-81-41-06787; R-1
A33: =A32+1 -> 23 | C33: A367-040-81-41-06788; R-2
A34: =A33+1 -> 24 | C34: A367-040-81-41-06790; R-0
A35: =A34+1 -> 25 | B35: Area-24 | C35: A367-040-81-41-06705 | D35: Bridge drg 06705 issued on 25.08.20 by EIL, but drg not received from NFC. | F35: Resolved, Drg. Received on 1-1-2021
A36: =A35+1 -> 26 | B36: Area-25 | C36: A367-040-81-41-06791_Rev-0 | D36: 1. Regarding Area-25 pipe rack structure crossing the Overhead electrical transmission line. So the design drawing may change. Due to this reason detail engineering not done. 2. TPL Engg comments: Table-1 does not include Tier-1 & Tier-2 levels. Please confirm levels marked in elevation can be followed or not. As per Table-1 no of cable trays are 2, however section 1-1, cable tray marked are 6. Please confirm. 3. TPL Engg comments: Table-1 does not include Tier-1 & Tier-2 levels. Please confirm levels marked in elevation can be followed or not. As per Table-1 no of cable trays are 2, however section 1-1, cable tray marked are 6. Please confirm. | F36: Site Revised foundation Drawings shared by NFC on Jul'21, So progress effected. Moreover, the progress affected due to the High Tension Overhead Transmission Lines above the foundations. In addition to the above the PR24 to PR25 road crossing bridge affected due to the OHT line.
A37: =A36+1 -> 27 | C37: A367-040-81-41-06792_Rev-0
A38: =A37+1 -> 28 | C38: A367-040-81-41-06793_Rev-0
A39: =A38+1 -> 29 | C39: A367-040-81-41-06794_Rev-0
A40: =A39+1 -> 30 | C40: A367-040-81-41-06795_Rev-0
A41: =A40+1 -> 31 | C41: A367-040-81-41-06796_Rev-0
...

Sheet Piping Constraint
A1: List of Piping work related RFI pending from EIL/NFC - As on date 10-Oct-2021
A3: Sl.No. | B3: Area No. | C3: Drawing No. | D3: Observations | E3: Remarks | F3: As on date Status
A4: 1 | B4: General | C4: SOQ/SOR & Piping GAD | D4: There is no supply item of 2" full coupling (Galv) SCRF in the SOQ/SOR w.r.t. the Galv SCRM pipes in SOQ/SOR - Need to be resolved at the earliest. | E4: Intimated through email by 28-Oct-20 & reminder on 21-Nov-20. | F4: As discussed with NFC on 17.03.21 TPL has to make SOQ missing Item list and submission for approval. The same is under progress.
A5: =A4+1 -> 2 | D5: There is no supply item of 4" full coupling (Galv) SCRF in the SOQ/SOR w.r.t. the Galv SCRM pipes in SOQ/SOR - Need to be resolved at the earliest.
A6: =A5+1 -> 3 | D6: There is no supply item of 6" full coupling (Galv) SCRF in the SOQ/SOR w.r.t. the Galv SCRM pipes in SOQ/SOR - Need to be resolved at the earliest.
A7: =A6+1 -> 4 | D7: There is no supply item for 3" SOFF Flange (rubber lined), w.r.t. the supply items for rubber lined pipes with plain end & supply item for rubber lined 90deg elbow with Bevel end. The execution methodology for rubber line piping shall be, we will procure bare pipe & bare elbow, spools will be fabricated with flange welded on both ends, rubber lining shall be done on spools, spools will be erected & connected through flange bolting - Need to be resolved at the earliest.
A8: =A7+1 -> 5 | D8: Wherever the RW & FW encounters underground road/ramp crossing occurs - hume pipes/RCC trenches/pipe culverts front required as applicable in drawings from Plants & Non-Plants - Need to be resolved at the earliest. | E8: Intimating in the Daily Progress Report.
A9: =A8+1 -> 6 | D9: Wherever the utility/process piping encounters underground road/ramp crossing occurs - hume pipes/RCC trenches/pipe culverts front required as applicable in drawings from Plants & Non-Plants - Need to be resolved at the earliest.
A10: 7 | D10: Service wise, Size wise & MOC wise pipe support details on the pipe rack need to be provided by EIL/NFC. In piping GAD drawing the same is not shown. - Received , BOM need to be made.
A11: 8 | B11: Area-4 | C11: A367-000-16-43-0041_Rev-2 | D11: The pipeline 25-NG-041-1503-A21A is shown in Area-1 to 3 piping GAD (A367-000-16-43-0011_Rev-1 ; A367-000-16-43-0021_Rev-0; A367-000-16-43-0031_Rev-0) but the same is not shown in the Area-4&5 drawing, but the same is shown again in Area-6 piping GAD (A367-000-16-43-0061_Rev-1) - Need to be resolved at the earliest. | E11: Observed while reviewing the piping GAD drawings. | F11: Still Pending from NFC/EIL
A12: 9 | B12: Area-5 | C12: A367-000-16-43-0051_Rev-1
A13: 10 | B13: Area-5 | C13: A367-000-16-43-0051_Rev-1 | D13: In the Area-5 piping GAD there are 14 pipelines shown, whereas in the Area-6 piping GAD there is 16 pipelines shown that too in the shuffled manner - Need to be resolved at the earliest.
A14: 11 | B14: Area-6 | C14: A367-000-16-43-0061_Rev-1
A15: 12 | B15: Area-6 | C15: A367-000-16-43-0061_Rev-1 | D15: In Area-6 Piping GAD drawing sheet-2 of 2 is not available. Moreover, 6-47 & 48 column shown in piping GAD but the same is not shown in corresponding Area-6 pipe rack structural drawing - Need to be resolved at the earliest.
A17: Note: | B17: 1. This shall not to be considered as the final RFI list related to piping work, the RFI shall increase based on the detail engineering.

Sheet Hindrance Register
A1: 340092 Piping Project
A2: S.No | B2: Date | C2: Reason for stoppage | D2: Progress Effected no.of Hours | E2: Remarks
A3: 1 | B3: 44256 | C3: Work stopped NFC site because of 1 workmen death at NPCIL site | D3: 24 Hrs
A4: 2 | B4: 44256 | C4: Area-13,14,23 & 24 Drawing Approval pending from NFC | E4: Cleared on 13-03-21
A5: 3 | B5: 44256 | C5: Area-06 Bridge Erection Hold from NFC | E5: Cleared on 15-03-21
A6: 4 | B6: 44270 | C6: Area-15(7 Foundations) , 16(7 foundations) Drawing Hold from NFC
A7: 5 | B7: 44287 | C7: Vendor Approval for Fuel Dispensing Unit | E7: Cleared on
A8: 6 | B8: 44287 | C8: Breathing Air Bullet platform and drawings confirmation to Proceed
A9: 7 | B9: 44287 | C9: Diesel Storage Tanks Drawings Approval
A10: 8 | B10: 44287 | C10: Diesel Storage Tanks Input requirment for Peso Approval
A11: 9 | B11: 44287 | C11: Ammonia Cracker P&ID and QA Approval
A12: 10 | B12: 44287 | C12: Rubber Lined items isometric drawing review and approval confirmation on NON-SOQ Items
A13: 11 | B13: 44287 | C13: Specifications and painting confirmation for handrail, Gratings, Ladder and Chequered Plate
A14: 12 | B14: 44287 | C14: Confirmation and Drawings for water Service, Valve SOQ in civil Structure
A15: 13 | B15: 44287 | C15: Confirmation on Valve Technical Clarification
A16: 14 | B16: 44287 | C16: Raw Water pipe line - Non SOQ quantity & items need to be confirmed.
A17: 15 | B17: 44287 | C17: Pipe Trench required for Underground piping (road crossings & PFFF area).
A18: 16 | B18: 44297 | C18: Progress Affected due to Powershutdown on 11-Apr-2021 | D18: Half Day
A19: 17 | B19: 44298 | C19: Progress Affected due to Powershutdown on 12-Apr-2021 | D19: Full Day
A20: 18 | B20: 44314 | C20: Progress Affected due to Powershutdown on 28-Apr-2021 | D20: Half Day
A21: 19 | B21: 44316 | C21: Breathing Air Bullet 11 no's arrived at site foundations required to erect the same ASAP
A22: 20 | B22: 13/5/2021 | C22: Progress Affected due to Powershutdown on 12-May-2021 (AREA-11) | D22: 8 HRS
A23: 21 | B23: 22/5/2021 | C23: Progress Affected because of heavy showers (18.00-19.30) | D23: 1.5 hrs
A24: 22 | B24: 44344 | C24: Progress Affected because of heavy showers(19.15 - 22.00) | D24: 3.75hrs
A25: 23 | B25: 44349 | C25: Progress Affected because of heavy showers(18.00 - 19.30) | D25: 1.5hrs
A26: 24 | B26: 44354 | C26: Progress Affected Due to Power cut | D26: 30 min
A27: 25 | B27: 44364 | C27: Progress Affected because of heavy showers(12.30 - 13.10) | D27: 40 min
A28: 26 | B28: 44365 | C28: Progress Affected because of heavy showers(19.30 - 20.20) | D28: 50 min
A29: 27 | B29: 44335 | C29: Progress Affected because of Power shutdown(9.54 - 10.17) | D29: 23 min
A30: 28 | B30: 44368 | C30: Progress Affected because of heavy showers(15.55 - 16.45) | D30: 50 min
A31: 29 | B31: 44368 | C31: Progress Affected because of heavy showers(17.03 - 18.15) | D31: 1hr 12min
A32: 30 | B32: 44369 | C32: Progress Affected because of heavy showers(18.20 - 19.00) | D32: 40 min
A33: 31 | B33: 44370 | C33: Progress Affected because of heavy showers(14.35 - 15.50) | D33: 1hr 15min
A34: 32 | B34: 44370 | C34: Progress Affected because of Power shutdown(16.20 - 17.20) | D34: 1hr
A35: 33 | B35: 44370 | C35: Progress Affected because of heavy showers(17.20 - 17.45) | D35: 25 min
A36: 34 | B36: 44370 | C36: Progress Affected because of Power shutdown(19.10 - 19.50) | D36: 40 min
A37: 35 | B37: 44372 | C37: Progress Affected because of Power shutdown(9.37 - 10.30) | D37: 1hr7min | E37: area 11
A38: 36 | B38: 44376 | C38: Progress Affected because of Power shutdown(multiple) | D38: 2hr45min
A39: 37 | B39: 44389 | C39: Progress Affected because of heavy showers(19.20 - 19.30) | D39: 10 MIN
A40: 38 | B40: 44390 | C40: Progress Affected because of heavy showers(17.00 - 17.50) | D40: 50 MIN
...

Sheet Summary
B1: PIPING | H1: PIPE RACK STRUCTURE | N1: TOTAL MANPOWER
B2: Pipes supply (mtr) | C2: blasting (mtrs) | D2: painting (mtrs) | E2: Fit up(id) | F2: Welding(id) | G2: placing(IM) | H2: Structural Supply (MT) | J2: Erection(MT) | L2: Alignment (MT) | M2: Welding (MT) | N2: STAFF | O2: LABOUR
A3: SCOPE | B3: =Progress!D9 -> 107231 | C3: =Progress!D10 -> 75182 | D3: =Progress!D11 -> 75182 | E3: =Progress!D22 -> 123470 | F3: =Progress!D23 -> 123470 | G3: =Progress!D26 -> 489572 | H3: =Progress!D64 -> 4400 | J3: =Progress!D66 -> 4400 | L3: 4400 | M3: 4400
A4: PLANNED (AUG) | B4: =Progress!F9 -> 5000 | C4: =Progress!F10 -> 6000 | D4: =Progress!F11 -> 6000 | E4: =Progress!F22 -> 10000 | F4: =Progress!F23 -> 10000 | G4: =Progress!F26 -> 40000 | H4: =Progress!F64 -> 400 | J4: =Progress!F66 -> 500 | L4: 400 | M4: 400 | N4: =' Manpower & Machinery'!H32 -> 58 | O4: =' Manpower & Machinery'!H52 -> 272
A5: Today (21-08-2021) | B5: =Progress!H9 -> 0 | C5: =Progress!H10 -> 0 | D5: =Progress!H11 -> 0 | E5: =Progress!H22 -> 78 | F5: =Progress!H23 -> 274 | G5: =Progress!H26 -> 1728 | H5: =Progress!H64 -> 0 | J5: =Progress!H66 -> 10 | L5: =Progress!H67 -> 7 | M5: =Progress!H68 -> 12
A6: Cumulative- August | B6: =Progress!I9 -> 0 | C6: =Progress!I10 -> 3066.93 | D6: =Progress!I11 -> 3066.93 | E6: =Progress!I22 -> 7652 | F6: =Progress!I23 -> 7696.5 | G6: =Progress!I26 -> 37169.88 | H6: =Progress!I64 -> 0 | J6: =Progress!I66 -> 189.6 | L6: =Progress!I67 -> 249.7 | M6: =Progress!I68 -> 576.7 | N6: =SUM(N4,O4) -> 330
A7: Total (up to date) | B7: =Progress!J9 -> 95680 | C7: =Progress!J10 -> 52561.93 | D7: =Progress!J11 -> 52561.93 | E7: =Progress!J22 -> 29674 | F7: =Progress!J23 -> 29718.5 | G7: =Progress!J26 -> 183767.88 | H7: =Progress!J64 -> 3383 | J7: =Progress!J66 -> 2349.7 | L7: =Progress!J67 -> 1707.5 | M7: =Progress!J68 -> 2374.4
A8: Manpower Strength | B8: STAFF | C8: =' Manpower & Machinery'!E32 -> 14 | D8: LABOUR | E8: =' Manpower & Machinery'!E52 -> 149 | H8: STAFF | I8: =' Manpower & Machinery'!D32 -> 27 | J8: LABOUR | K8: =' Manpower & Machinery'!D52 -> 111
B9: INDUCTION (NEW) | H9: 0

Sheet Sheet1
